Workbook

Sheet Dados
A1: Gráficos de Distribuição | D1: Disciplina de Inventário e Avaliação da Biodiversidade - PUCPR - Prof Rodrigo Kersten
A2: PAP (cm) | B2: Alt (m)
A3: 19.6 | B3: 4.5
A4: 22.1 | B4: 4.5 | E4: Colar apenas os dados de PAP e Altura nas Colunas correspondentes - Até 500 indivíduos -
A5: 18.1 | B5: 4.5
A6: 23.4 | B6: 5
A7: 27 | B7: 6
A8: 29.8 | B8: 4
A9: 56.4 | B9: 6
A10: 28.7 | B10: 5
A11: 16.6 | B11: 4
A12: 22 | B12: 4
A13: 45 | B13: 6
A14: 52 | B14: 5
A15: 21.5 | B15: 3 | E15: 1- APAGAR OS DADOS EXISTENTES
A16: 46.5 | B16: 8
A17: 149.5 | B17: 10 | E17: 2- COLAR SOMENTE VALORES
A18: 53.1 | B18: 8
A19: 96.4 | B19: 9
A20: 69 | B20: 8
A21: 24 | B21: 7
A22: 56.8 | B22: 7
A23: 36.8 | B23: 7
A24: 23.2 | B24: 5
A25: 18.5 | B25: 5
A26: 18 | B26: 3
A27: 17.2 | B27: 3.5
A28: 19.6 | B28: 4
A29: 18 | B29: 4
... A502: 37.7 | B502: 13

Sheet Gráfico DAP
Q1: PAP | R1: DAP | S1: Classes | T1: N | U1: Classes
Q2: =IF(Dados!A3="","",Dados!A3) -> 19.6 | R2: =Q2/PI() -> 6.2388738 | S2: 9.9 | T2: {=FREQUENCY(R2:R501,S2:S14)} -> 182 | U2: <10
Q3: =IF(Dados!A4="","",Dados!A4) -> 22.1 | R3: =Q3/PI() -> 7.0346485 | S3: 14.9 | T3: 90 | U3: 10-15
Q4: =IF(Dados!A5="","",Dados!A5) -> 18.1 | R4: =Q4/PI() -> 5.7614089 | S4: 19.9 | T4: 70 | U4: 15-20
Q5: =IF(Dados!A6="","",Dados!A6) -> 23.4 | R5: =Q5/PI() -> 7.4484513 | S5: 24.9 | T5: 58 | U5: 20-25
Q6: =IF(Dados!A7="","",Dados!A7) -> 27 | R6: =Q6/PI() -> 8.5943669 | S6: 29.9 | T6: 41 | U6: 25-30
Q7: =IF(Dados!A8="","",Dados!A8) -> 29.8 | R7: =Q7/PI() -> 9.4856346 | S7: 34.9 | T7: 26 | U7: 30-35
Q8: =IF(Dados!A9="","",Dados!A9) -> 56.4 | R8: =Q8/PI() -> 17.952678 | S8: 39.9 | T8: 16 | U8: 35-40
Q9: =IF(Dados!A10="","",Dados!A10) -> 28.7 | R9: =Q9/PI() -> 9.1354937 | S9: 44.9 | T9: 7 | U9: 40-45
Q10: =IF(Dados!A11="","",Dados!A11) -> 16.6 | R10: =Q10/PI() -> 5.2839441 | S10: 49.9 | T10: 4 | U10: 45-50
Q11: =IF(Dados!A12="","",Dados!A12) -> 22 | R11: =Q11/PI() -> 7.0028175 | S11: 74.9 | T11: 6 | U11: 50-75
Q12: =IF(Dados!A13="","",Dados!A13) -> 45 | R12: =Q12/PI() -> 14.323945 | S12: 99.9 | T12: 0 | U12: 75-100
Q13: =IF(Dados!A14="","",Dados!A14) -> 52 | R13: =Q13/PI() -> 16.552114 | S13: 200 | T13: 0 | U13: >100
Q14: =IF(Dados!A15="","",Dados!A15) -> 21.5 | R14: =Q14/PI() -> 6.8436626 | T14: 0
Q15: =IF(Dados!A16="","",Dados!A16) -> 46.5 | R15: =Q15/PI() -> 14.80141
Q16: =IF(Dados!A17="","",Dados!A17) -> 149.5 | R16: =Q16/PI() -> 47.587328
Q17: =IF(Dados!A18="","",Dados!A18) -> 53.1 | R17: =Q17/PI() -> 16.902255
Q18: =IF(Dados!A19="","",Dados!A19) -> 96.4 | R18: =Q18/PI() -> 30.685073
Q19: =IF(Dados!A20="","",Dados!A20) -> 69 | R19: =Q19/PI() -> 21.963382
Q20: =IF(Dados!A21="","",Dados!A21) -> 24 | R20: =Q20/PI() -> 7.6394373
Q21: =IF(Dados!A22="","",Dados!A22) -> 56.8 | R21: =Q21/PI() -> 18.080002
Q22: =IF(Dados!A23="","",Dados!A23) -> 36.8 | R22: =Q22/PI() -> 11.713804
K23: DAP Min | L23: =MIN(R2:R501) -> 4.5836624 | Q23: =IF(Dados!A24="","",Dados!A24) -> 23.2 | R23: =Q23/PI() -> 7.3847894
K24: DAP Max | L24: =MAX(R2:R501) -> 59.205639 | Q24: =IF(Dados!A25="","",Dados!A25) -> 18.5 | R24: =Q24/PI() -> 5.8887329
Q25: =IF(Dados!A26="","",Dados!A26) -> 18 | R25: =Q25/PI() -> 5.729578
Q26: =IF(Dados!A27="","",Dados!A27) -> 17.2 | R26: =Q26/PI() -> 5.47493
Q27: =IF(Dados!A28="","",Dados!A28) -> 19.6 | R27: =Q27/PI() -> 6.2388738
Q28: =IF(Dados!A29="","",Dados!A29) -> 18 | R28: =Q28/PI() -> 5.729578
Q29: =IF(Dados!A30="","",Dados!A30) -> 52 | R29: =Q29/PI() -> 16.552114
Q30: =IF(Dados!A31="","",Dados!A31) -> 29 | R30: =Q30/PI() -> 9.2309867
Q31: =IF(Dados!A32="","",Dados!A32) -> 46.5 | R31: =Q31/PI() -> 14.80141
Q32: =IF(Dados!A33="","",Dados!A33) -> 50.2 | R32: =Q32/PI() -> 15.979156
Q33: =IF(Dados!A34="","",Dados!A34) -> 39.5 | R33: =Q33/PI() -> 12.573241
Q34: =IF(Dados!A35="","",Dados!A35) -> 65.2 | R34: =Q34/PI() -> 20.753805
Q35: =IF(Dados!A36="","",Dados!A36) -> 85.2 | R35: =Q35/PI() -> 27.120002
Q36: =IF(Dados!A37="","",Dados!A37) -> 64.2 | R36: =Q36/PI() -> 20.435495
... Q501: =IF(Dados!A502="","",Dados!A502) -> 37.7 | R501: =Q501/PI() -> 12.000283
R517: =IF(Dados!A518="","",Dados!A518)
R518: =IF(Dados!A519="","",Dados!A519)
R519: =IF(Dados!A520="","",Dados!A520)
...

Sheet Gráfico Alturas
Q1: Alt | S1: Classes | T1: n | U1: Classes de Altura
Q2: =IF(Dados!B3="","",Dados!B3) -> 4.5 | S2: 2.99 | T2: {=FREQUENCY(Q2:Q501,S2:S13)} -> 14 | U2: <3
Q3: =IF(Dados!B4="","",Dados!B4) -> 4.5 | S3: 3.99 | T3: 17 | U3: 3
Q4: =IF(Dados!B5="","",Dados!B5) -> 4.5 | S4: 4.99 | T4: 42 | U4: 4
Q5: =IF(Dados!B6="","",Dados!B6) -> 5 | S5: 5.99 | T5: 56 | U5: 5
Q6: =IF(Dados!B7="","",Dados!B7) -> 6 | S6: 6.99 | T6: 56 | U6: 6
Q7: =IF(Dados!B8="","",Dados!B8) -> 4 | S7: 7.99 | T7: 72 | U7: 7
Q8: =IF(Dados!B9="","",Dados!B9) -> 6 | S8: 8.99 | T8: 71 | U8: 8
Q9: =IF(Dados!B10="","",Dados!B10) -> 5 | S9: 9.99 | T9: 55 | U9: 9
Q10: =IF(Dados!B11="","",Dados!B11) -> 4 | S10: 10.99 | T10: 55 | U10: 10
Q11: =IF(Dados!B12="","",Dados!B12) -> 4 | S11: 11.99 | T11: 28 | U11: 11
Q12: =IF(Dados!B13="","",Dados!B13) -> 6 | S12: 12.99 | T12: 19 | U12: 12
Q13: =IF(Dados!B14="","",Dados!B14) -> 5 | S13: 20 | T13: 15 | U13: >12
Q14: =IF(Dados!B15="","",Dados!B15) -> 3 | T14: 0
Q15: =IF(Dados!B16="","",Dados!B16) -> 8
Q16: =IF(Dados!B17="","",Dados!B17) -> 10
Q17: =IF(Dados!B18="","",Dados!B18) -> 8
Q18: =IF(Dados!B19="","",Dados!B19) -> 9
Q19: =IF(Dados!B20="","",Dados!B20) -> 8
Q20: =IF(Dados!B21="","",Dados!B21) -> 7
Q21: =IF(Dados!B22="","",Dados!B22) -> 7
Q22: =IF(Dados!B23="","",Dados!B23) -> 7
K23: Alt Min | L23: =MIN(Q2:Q501) -> 1.5 | Q23: =IF(Dados!B24="","",Dados!B24) -> 5
K24: Alt Max | L24: =MAX(Q2:Q501) -> 14 | Q24: =IF(Dados!B25="","",Dados!B25) -> 5
Q25: =IF(Dados!B26="","",Dados!B26) -> 3
Q26: =IF(Dados!B27="","",Dados!B27) -> 3.5
Q27: =IF(Dados!B28="","",Dados!B28) -> 4
Q28: =IF(Dados!B29="","",Dados!B29) -> 4
Q29: =IF(Dados!B30="","",Dados!B30) -> 6
Q30: =IF(Dados!B31="","",Dados!B31) -> 6
Q31: =IF(Dados!B32="","",Dados!B32) -> 8
Q32: =IF(Dados!B33="","",Dados!B33) -> 8
Q33: =IF(Dados!B34="","",Dados!B34) -> 8
Q34: =IF(Dados!B35="","",Dados!B35) -> 9
Q35: =IF(Dados!B36="","",Dados!B36) -> 10
Q36: =IF(Dados!B37="","",Dados!B37) -> 8
... Q501: =IF(Dados!B502="","",Dados!B502) -> 13

Sheet Gráfico PAP
R1: PAP | S1: Classes | T1: no. Ind. | U1: Classes de Perímetros
R2: =IF(Dados!A3="","",Dados!A3) -> 19.6 | S2: 19.99 | T2: {=FREQUENCY(R2:R501,S2:S13)} -> 56 | U2: <20
R3: =IF(Dados!A4="","",Dados!A4) -> 22.1 | S3: 29.99 | T3: 113 | U3: 20-29
R4: =IF(Dados!A5="","",Dados!A5) -> 18.1 | S4: 39.99 | T4: 68 | U4: 30-39
R5: =IF(Dados!A6="","",Dados!A6) -> 23.4 | S5: 49.99 | T5: 47 | U5: 40-49
R6: =IF(Dados!A7="","",Dados!A7) -> 27 | S6: 59.99 | T6: 50 | U6: 50-59
R7: =IF(Dados!A8="","",Dados!A8) -> 29.8 | S7: 69.99 | T7: 42 | U7: 60-69
R8: =IF(Dados!A9="","",Dados!A9) -> 56.4 | S8: 79.99 | T8: 27 | U8: 70-79
R9: =IF(Dados!A10="","",Dados!A10) -> 28.7 | S9: 89.99 | T9: 32 | U9: 80-89
R10: =IF(Dados!A11="","",Dados!A11) -> 16.6 | S10: 99.99 | T10: 20 | U10: 90-99
R11: =IF(Dados!A12="","",Dados!A12) -> 22 | S11: 149.99 | T11: 39 | U11: 100-150
R12: =IF(Dados!A13="","",Dados!A13) -> 45 | S12: 199.99 | T12: 6 | U12: 150-200
R13: =IF(Dados!A14="","",Dados!A14) -> 52 | S13: 300 | T13: 0 | U13: 200-300
R14: =IF(Dados!A15="","",Dados!A15) -> 21.5 | T14: 0
R15: =IF(Dados!A16="","",Dados!A16) -> 46.5
R16: =IF(Dados!A17="","",Dados!A17) -> 149.5
R17: =IF(Dados!A18="","",Dados!A18) -> 53.1
R18: =IF(Dados!A19="","",Dados!A19) -> 96.4
R19: =IF(Dados!A20="","",Dados!A20) -> 69
R20: =IF(Dados!A21="","",Dados!A21) -> 24
R21: =IF(Dados!A22="","",Dados!A22) -> 56.8
R22: =IF(Dados!A23="","",Dados!A23) -> 36.8
K23: PAP Min | L23: =MIN(R2:R501) -> 14.4 | R23: =IF(Dados!A24="","",Dados!A24) -> 23.2
K24: PAP Max | L24: =MAX(R2:R501) -> 186 | R24: =IF(Dados!A25="","",Dados!A25) -> 18.5
R25: =IF(Dados!A26="","",Dados!A26) -> 18
R26: =IF(Dados!A27="","",Dados!A27) -> 17.2
R27: =IF(Dados!A28="","",Dados!A28) -> 19.6
R28: =IF(Dados!A29="","",Dados!A29) -> 18
R29: =IF(Dados!A30="","",Dados!A30) -> 52
R30: =IF(Dados!A31="","",Dados!A31) -> 29
R31: =IF(Dados!A32="","",Dados!A32) -> 46.5
R32: =IF(Dados!A33="","",Dados!A33) -> 50.2
R33: =IF(Dados!A34="","",Dados!A34) -> 39.5
R34: =IF(Dados!A35="","",Dados!A35) -> 65.2
R35: =IF(Dados!A36="","",Dados!A36) -> 85.2
R36: =IF(Dados!A37="","",Dados!A37) -> 64.2
... R610: =IF(Dados!A611="","",Dados!A611)
