Workbook

Sheet DADOS
C1: Dados Originais do Levantamento (colar sem formatação) | J1: Dados Gerais sobre a área | N1: Disciplina de Inventário e Avaliação da Biodiversidade
C2: Parcela | D2: Espécie | E2: PAP | F2: Alt | J2: Preencher apenas os dados das células em branco | N2: Prof. Dr. Rodrigo de Andrade Kersten
C3: 1 | D3: Allophylus edulis | E3: 19.6 | F3: 4.5 | J3: Tamanho total da área considerada | K3: 5000
C4: 1 | D4: Allophylus edulis | E4: 22.1 | F4: 4.5 | J4: Tamanho da parcela (em m2) | K4: 100
C5: 1 | D5: Bauhinia forficata | E5: 18.1 | F5: 4.5 | J5: Precisão requerida | K5: 0.2
C6: 1 | D6: Bauhinia forficata | E6: 23.4 | F6: 5 | J6: Nível de probabilidade | K6: 0.9
C7: 1 | D7: Bauhinia forficata | E7: 27 | F7: 6
C8: 1 | D8: Dracaena marginata | E8: 29.8 | F8: 4 | J8: Número de parcelas alocadas (n) | K8: =calc!B8 -> 30
C9: 1 | D9: Gymnanthes klotzschiana | E9: 56.4 | F9: 6 | J9: Tamanho da parcela (ha) | K9: =K4/10000 -> 0.01
C10: 1 | D10: Gymnanthes klotzschiana | E10: 28.7 | F10: 5 | J10: Número máximo de parcelas (N) | K10: =ROUNDUP(K3/K4,0) -> 50
C11: 1 | D11: Gymnanthes klotzschiana | E11: 16.6 | F11: 4 | J11: Área total amostrada (ha) | K11: =K8*K9 -> 0.3
C12: 1 | D12: Ocotea puberulla | E12: 22 | F12: 4 | J12: Percentual de Amostragen (n/N) | K12: =calc!B12 -> 0.6
C13: 1 | D13: Senna macranthera | E13: 45 | F13: 6
C14: 1 | D14: Senna macranthera | E14: 52 | F14: 5
C15: 1 | D15: Senna macranthera | E15: 21.5 | F15: 3
C16: 1 | D16: Bauhinia forficata | E16: 46.5 | F16: 8 | J16: Suficiencia (segundo o volume de madeira)
C17: 1 | D17: Bauhinia forficata | E17: 149.5 | F17: 10
C18: 1 | D18: Ligustrum lucidum | E18: 53.1 | F18: 8 | J18: =calc!A17 -> Atingiu a suficiência
C19: 1 | D19: Ligustrum lucidum | E19: 96.4 | F19: 9
C20: 1 | D20: Ocotea puberulla | E20: 69 | F20: 8
C21: 2 | D21: Annona emarginata | E21: 24 | F21: 7
C22: 2 | D22: Bauhinia forficata | E22: 56.8 | F22: 7 | J22: no. mínimo de parcelas para a suficiência
C23: 2 | D23: Senna macranthera | E23: 36.8 | F23: 7
C24: 2 | D24: Allophylus edulis | E24: 23.2 | F24: 5 | J24: =calc!A21 -> 15
C25: 2 | D25: Allophylus edulis | E25: 18.5 | F25: 5
C26: 2 | D26: Bauhinia forficata | E26: 18 | F26: 3
C27: 2 | D27: Bauhinia forficata | E27: 17.2 | F27: 3.5
C28: 2 | D28: Eriobotrya japonica | E28: 19.6 | F28: 4
C29: 2 | D29: Gymnanthes klotzschiana | E29: 18 | F29: 4
C30: 2 | D30: Gymnanthes klotzschiana | E30: 52 | F30: 6
C31: 2 | D31: Solanum sanctae-catharinae | E31: 29 | F31: 6
C32: 2 | D32: Bauhinia forficata | E32: 46.5 | F32: 8
C33: 2 | D33: Bauhinia forficata | E33: 50.2 | F33: 8
C34: 2 | D34: Bauhinia forficata | E34: 39.5 | F34: 8
C35: 2 | D35: Bauhinia forficata | E35: 65.2 | F35: 9
C36: 2 | D36: Gymnanthes klotzschiana | E36: 85.2 | F36: 10
... C626: 30 | D626: Schinus terebinthifolium | E626: 102.5 | F626: 10

Sheet calc
A1: Informações do Levantamento >> | D1: DADOS DAS PARCELAS>> | J1: Vol. ( fator de forma)>> | M1: FF = | N1: 0.8 | Q1: Volume por parcela>> | V1: Suficiência>>
A2: Preencher apenas os dados das células em branco | E2: Parc | F2: PAP | G2: Alt | K2: DAP | L2: AB | M2: Vol | N2: Vol (FF) | R2: Parcela | S2: Vol (m3)
A3: Tamanho total da área considerada | B3: =DADOS!K3 -> 5000 | E3: =IF(DADOS!C3="","",DADOS!C3) -> 1 | F3: =IF(DADOS!E3="","",DADOS!E3) -> 19.6 | G3: =IF(DADOS!F3="","",DADOS!F3) -> 4.5 | K3: =IF(F3="","",F3/PI()) -> 6.2388738 | L3: =IF(K3="","",(PI()*K3^2)/40000) -> 0.0030570481 | M3: =IF(L3="","",L3*G3) -> 0.013756717 | N3: =IF(M3="","",M3*N$1) -> 0.011005373 | R3: {=IF(_xlfn.UNIQUE(E3:E10000,FALSE,FALSE)=0,"",_xlfn.UNIQUE(E3:E10000,FALSE,FALSE))} -> 1 | S3: =IF(R3="","",SUMIFS($N$3:$N$10000,$E$3:$E$10000,R3)) -> 2.893093 | Y3: População
A4: Tamanho da parcela (em m2) | B4: =DADOS!K4 -> 100 | E4: =IF(DADOS!C4="","",DADOS!C4) -> 1 | F4: =IF(DADOS!E4="","",DADOS!E4) -> 22.1 | G4: =IF(DADOS!F4="","",DADOS!F4) -> 4.5 | K4: =IF(F4="","",F4/PI()) -> 7.0346485 | L4: =IF(K4="","",(PI()*K4^2)/40000) -> 0.0038866433 | M4: =IF(L4="","",L4*G4) -> 0.017489895 | N4: =IF(M4="","",M4*N$1) -> 0.013991916 | R4: 2 | S4: =IF(R4="","",SUMIFS($N$3:$N$10000,$E$3:$E$10000,R4)) -> 3.9618707 | W4: Fator de correção | X4: =1-B12 -> 0.4 | Y4: =IF(X4>=0.98,"Infinita","Finita") -> Finita
A5: Precisão requerida | B5: =DADOS!K5 -> 0.2 | E5: =IF(DADOS!C5="","",DADOS!C5) -> 1 | F5: =IF(DADOS!E5="","",DADOS!E5) -> 18.1 | G5: =IF(DADOS!F5="","",DADOS!F5) -> 4.5 | K5: =IF(F5="","",F5/PI()) -> 5.7614089 | L5: =IF(K5="","",(PI()*K5^2)/40000) -> 0.0026070375 | M5: =IF(L5="","",L5*G5) -> 0.011731669 | N5: =IF(M5="","",M5*N$1) -> 0.0093853352 | R5: 3 | S5: =IF(R5="","",SUMIFS($N$3:$N$10000,$E$3:$E$10000,R5)) -> 5.2577898
A6: Nível de probabilidade | B6: =DADOS!K6 -> 0.9 | E6: =IF(DADOS!C6="","",DADOS!C6) -> 1 | F6: =IF(DADOS!E6="","",DADOS!E6) -> 23.4 | G6: =IF(DADOS!F6="","",DADOS!F6) -> 5 | K6: =IF(F6="","",F6/PI()) -> 7.4484513 | L6: =IF(K6="","",(PI()*K6^2)/40000) -> 0.004357344 | M6: =IF(L6="","",L6*G6) -> 0.02178672 | N6: =IF(M6="","",M6*N$1) -> 0.017429376 | R6: 4 | S6: =IF(R6="","",SUMIFS($N$3:$N$10000,$E$3:$E$10000,R6)) -> 2.8186449 | W6: Volume médio | X6: =AVERAGE(S3:S1000) -> 4.5836188
E7: =IF(DADOS!C7="","",DADOS!C7) -> 1 | F7: =IF(DADOS!E7="","",DADOS!E7) -> 27 | G7: =IF(DADOS!F7="","",DADOS!F7) -> 6 | K7: =IF(F7="","",F7/PI()) -> 8.5943669 | L7: =IF(K7="","",(PI()*K7^2)/40000) -> 0.0058011977 | M7: =IF(L7="","",L7*G7) -> 0.034807186 | N7: =IF(M7="","",M7*N$1) -> 0.027845749 | R7: 5 | S7: =IF(R7="","",SUMIFS($N$3:$N$10000,$E$3:$E$10000,R7)) -> 10.021156 | W7: Variância Amostral | X7: =_xlfn.VAR.S(S3:S1000) -> 6.1319538
A8: Número de parcelas alocadas (n) | B8: =COUNT(R3:R265) -> 30 | E8: =IF(DADOS!C8="","",DADOS!C8) -> 1 | F8: =IF(DADOS!E8="","",DADOS!E8) -> 29.8 | G8: =IF(DADOS!F8="","",DADOS!F8) -> 4 | K8: =IF(F8="","",F8/PI()) -> 9.4856346 | L8: =IF(K8="","",(PI()*K8^2)/40000) -> 0.0070667978 | M8: =IF(L8="","",L8*G8) -> 0.028267191 | N8: =IF(M8="","",M8*N$1) -> 0.022613753 | R8: 6 | S8: =IF(R8="","",SUMIFS($N$3:$N$10000,$E$3:$E$10000,R8)) -> 3.5355166 | W8: Desvio Padrão | X8: =_xlfn.STDEV.S(S3:S1000) -> 2.4762782
A9: Tamanho da parcela (ha) | B9: =B4/10000 -> 0.01 | E9: =IF(DADOS!C9="","",DADOS!C9) -> 1 | F9: =IF(DADOS!E9="","",DADOS!E9) -> 56.4 | G9: =IF(DADOS!F9="","",DADOS!F9) -> 6 | K9: =IF(F9="","",F9/PI()) -> 17.952678 | L9: =IF(K9="","",(PI()*K9^2)/40000) -> 0.025313275 | M9: =IF(L9="","",L9*G9) -> 0.15187965 | N9: =IF(M9="","",M9*N$1) -> 0.12150372 | R9: 7 | S9: =IF(R9="","",SUMIFS($N$3:$N$10000,$E$3:$E$10000,R9)) -> 2.2988528 | W9: Coeficiente de Variação | X9: =X8/X6 -> 0.54024524
A10: Número máximo de parcelas (N) | B10: =ROUNDUP(B3/B4,0) -> 50 | E10: =IF(DADOS!C10="","",DADOS!C10) -> 1 | F10: =IF(DADOS!E10="","",DADOS!E10) -> 28.7 | G10: =IF(DADOS!F10="","",DADOS!F10) -> 5 | K10: =IF(F10="","",F10/PI()) -> 9.1354937 | L10: =IF(K10="","",(PI()*K10^2)/40000) -> 0.0065547168 | M10: =IF(L10="","",L10*G10) -> 0.032773584 | N10: =IF(M10="","",M10*N$1) -> 0.026218867 | R10: 8 | S10: =IF(R10="","",SUMIFS($N$3:$N$10000,$E$3:$E$10000,R10)) -> 3.2163998
A11: Área total amostrada (ha) | B11: =B8*B9 -> 0.3 | E11: =IF(DADOS!C11="","",DADOS!C11) -> 1 | F11: =IF(DADOS!E11="","",DADOS!E11) -> 16.6 | G11: =IF(DADOS!F11="","",DADOS!F11) -> 4 | K11: =IF(F11="","",F11/PI()) -> 5.2839441 | L11: =IF(K11="","",(PI()*K11^2)/40000) -> 0.0021928368 | M11: =IF(L11="","",L11*G11) -> 0.0087713472 | N11: =IF(M11="","",M11*N$1) -> 0.0070170778 | R11: 9 | S11: =IF(R11="","",SUMIFS($N$3:$N$10000,$E$3:$E$10000,R11)) -> 3.4872222
A12: Percentual de Amostragen (n/N) | B12: =ROUNDUP(B8/B10,2) -> 0.6 | E12: =IF(DADOS!C12="","",DADOS!C12) -> 1 | F12: =IF(DADOS!E12="","",DADOS!E12) -> 22 | G12: =IF(DADOS!F12="","",DADOS!F12) -> 4 | K12: =IF(F12="","",F12/PI()) -> 7.0028175 | L12: =IF(K12="","",(PI()*K12^2)/40000) -> 0.0038515496 | M12: =IF(L12="","",L12*G12) -> 0.015406198 | N12: =IF(M12="","",M12*N$1) -> 0.012324959 | R12: 10 | S12: =IF(R12="","",SUMIFS($N$3:$N$10000,$E$3:$E$10000,R12)) -> 6.6984803 | W12: Variância da média | X12: =IF(X4>=0.98,X7/B8,X4*X7/B8) -> 0.081759385
E13: =IF(DADOS!C13="","",DADOS!C13) -> 1 | F13: =IF(DADOS!E13="","",DADOS!E13) -> 45 | G13: =IF(DADOS!F13="","",DADOS!F13) -> 6 | K13: =IF(F13="","",F13/PI()) -> 14.323945 | L13: =IF(K13="","",(PI()*K13^2)/40000) -> 0.016114438 | M13: =IF(L13="","",L13*G13) -> 0.096686628 | N13: =IF(M13="","",M13*N$1) -> 0.077349302 | R13: 11 | S13: =IF(R13="","",SUMIFS($N$3:$N$10000,$E$3:$E$10000,R13)) -> 9.191353 | W13: Erro padrão da Média | X13: =SQRT(X12) -> 0.28593598
E14: =IF(DADOS!C14="","",DADOS!C14) -> 1 | F14: =IF(DADOS!E14="","",DADOS!E14) -> 52 | G14: =IF(DADOS!F14="","",DADOS!F14) -> 5 | K14: =IF(F14="","",F14/PI()) -> 16.552114 | L14: =IF(K14="","",(PI()*K14^2)/40000) -> 0.021517748 | M14: =IF(L14="","",L14*G14) -> 0.10758874 | N14: =IF(M14="","",M14*N$1) -> 0.086070993 | R14: 12 | S14: =IF(R14="","",SUMIFS($N$3:$N$10000,$E$3:$E$10000,R14)) -> 4.7168037 | W14: t Student | X14: =_xlfn.T.INV.2T(1-B6,B8-1) -> 1.699127
E15: =IF(DADOS!C15="","",DADOS!C15) -> 1 | F15: =IF(DADOS!E15="","",DADOS!E15) -> 21.5 | G15: =IF(DADOS!F15="","",DADOS!F15) -> 3 | K15: =IF(F15="","",F15/PI()) -> 6.8436626 | L15: =IF(K15="","",(PI()*K15^2)/40000) -> 0.0036784686 | M15: =IF(L15="","",L15*G15) -> 0.011035406 | N15: =IF(M15="","",M15*N$1) -> 0.0088283247 | R15: 13 | S15: =IF(R15="","",SUMIFS($N$3:$N$10000,$E$3:$E$10000,R15)) -> 3.034101
E16: =IF(DADOS!C16="","",DADOS!C16) -> 1 | F16: =IF(DADOS!E16="","",DADOS!E16) -> 46.5 | G16: =IF(DADOS!F16="","",DADOS!F16) -> 8 | K16: =IF(F16="","",F16/PI()) -> 14.80141 | L16: =IF(K16="","",(PI()*K16^2)/40000) -> 0.017206639 | M16: =IF(L16="","",L16*G16) -> 0.13765311 | N16: =IF(M16="","",M16*N$1) -> 0.11012249 | R16: 14 | S16: =IF(R16="","",SUMIFS($N$3:$N$10000,$E$3:$E$10000,R16)) -> 2.4824203 | W16: Erro Amostral Absoluto | X16: =X14*X13 -> 0.48584155 | Y16: m3
A17: =IF(X17<=0.2,"Atingiu a suficiência", "Não atingiu a suficiência") -> Atingiu a suficiência | E17: =IF(DADOS!C17="","",DADOS!C17) -> 1 | F17: =IF(DADOS!E17="","",DADOS!E17) -> 149.5 | G17: =IF(DADOS!F17="","",DADOS!F17) -> 10 | K17: =IF(F17="","",F17/PI()) -> 47.587328 | L17: =IF(K17="","",(PI()*K17^2)/40000) -> 0.17785764 | M17: =IF(L17="","",L17*G17) -> 1.7785764 | N17: =IF(M17="","",M17*N$1) -> 1.4228611 | R17: 15 | S17: =IF(R17="","",SUMIFS($N$3:$N$10000,$E$3:$E$10000,R17)) -> 3.9982151 | W17: Erro Amostral Relativo | X17: =X14*X13/X6 -> 0.10599519
E18: =IF(DADOS!C18="","",DADOS!C18) -> 1 | F18: =IF(DADOS!E18="","",DADOS!E18) -> 53.1 | G18: =IF(DADOS!F18="","",DADOS!F18) -> 8 | K18: =IF(F18="","",F18/PI()) -> 16.902255 | L18: =IF(K18="","",(PI()*K18^2)/40000) -> 0.022437743 | M18: =IF(L18="","",L18*G18) -> 0.17950195 | N18: =IF(M18="","",M18*N$1) -> 0.14360156 | R18: 16 | S18: =IF(R18="","",SUMIFS($N$3:$N$10000,$E$3:$E$10000,R18)) -> 7.8962538
E19: =IF(DADOS!C19="","",DADOS!C19) -> 1 | F19: =IF(DADOS!E19="","",DADOS!E19) -> 96.4 | G19: =IF(DADOS!F19="","",DADOS!F19) -> 9 | K19: =IF(F19="","",F19/PI()) -> 30.685073 | L19: =IF(K19="","",(PI()*K19^2)/40000) -> 0.073951026 | M19: =IF(L19="","",L19*G19) -> 0.66555923 | N19: =IF(M19="","",M19*N$1) -> 0.53244739 | R19: 17 | S19: =IF(R19="","",SUMIFS($N$3:$N$10000,$E$3:$E$10000,R19)) -> 9.1798312
A20: Parcelas Necessárias | E20: =IF(DADOS!C20="","",DADOS!C20) -> 1 | F20: =IF(DADOS!E20="","",DADOS!E20) -> 69 | G20: =IF(DADOS!F20="","",DADOS!F20) -> 8 | K20: =IF(F20="","",F20/PI()) -> 21.963382 | L20: =IF(K20="","",(PI()*K20^2)/40000) -> 0.037886834 | M20: =IF(L20="","",L20*G20) -> 0.30309467 | N20: =IF(M20="","",M20*N$1) -> 0.24247574 | R20: 18 | S20: =IF(R20="","",SUMIFS($N$3:$N$10000,$E$3:$E$10000,R20)) -> 8.0312405 | W20: Erro Amostral Absoluto Aceitável | X20: =B5*X16/X17 -> 0.91672375 | Y20: m3
A21: =X22 -> 15 | E21: =IF(DADOS!C21="","",DADOS!C21) -> 2 | F21: =IF(DADOS!E21="","",DADOS!E21) -> 24 | G21: =IF(DADOS!F21="","",DADOS!F21) -> 7 | K21: =IF(F21="","",F21/PI()) -> 7.6394373 | L21: =IF(K21="","",(PI()*K21^2)/40000) -> 0.0045836624 | M21: =IF(L21="","",L21*G21) -> 0.032085637 | N21: =IF(M21="","",M21*N$1) -> 0.025668509 | R21: 19 | S21: =IF(R21="","",SUMIFS($N$3:$N$10000,$E$3:$E$10000,R21)) -> 2.9499465
E22: =IF(DADOS!C22="","",DADOS!C22) -> 2 | F22: =IF(DADOS!E22="","",DADOS!E22) -> 56.8 | G22: =IF(DADOS!F22="","",DADOS!F22) -> 7 | K22: =IF(F22="","",F22/PI()) -> 18.080002 | L22: =IF(K22="","",(PI()*K22^2)/40000) -> 0.025673602 | M22: =IF(L22="","",L22*G22) -> 0.17971522 | N22: =IF(M22="","",M22*N$1) -> 0.14377217 | R22: 20 | S22: =IF(R22="","",SUMIFS($N$3:$N$10000,$E$3:$E$10000,R22)) -> 5.4902949 | W22: Parcelas Necessárias | X22: =IF(X4>=0.98,X23,X24) -> 15
E23: =IF(DADOS!C23="","",DADOS!C23) -> 2 | F23: =IF(DADOS!E23="","",DADOS!E23) -> 36.8 | G23: =IF(DADOS!F23="","",DADOS!F23) -> 7 | K23: =IF(F23="","",F23/PI()) -> 11.713804 | L23: =IF(K23="","",(PI()*K23^2)/40000) -> 0.0107767 | M23: =IF(L23="","",L23*G23) -> 0.075436897 | N23: =IF(M23="","",M23*N$1) -> 0.060349517 | R23: 21 | S23: =IF(R23="","",SUMIFS($N$3:$N$10000,$E$3:$E$10000,R23)) -> 6.9678721 | W23: População Infinita | X23: =ROUNDUP((X14^2*X7/X20^2),0) -> 22
E24: =IF(DADOS!C24="","",DADOS!C24) -> 2 | F24: =IF(DADOS!E24="","",DADOS!E24) -> 23.2 | G24: =IF(DADOS!F24="","",DADOS!F24) -> 5 | K24: =IF(F24="","",F24/PI()) -> 7.3847894 | L24: =IF(K24="","",(PI()*K24^2)/40000) -> 0.0042831778 | M24: =IF(L24="","",L24*G24) -> 0.021415889 | N24: =IF(M24="","",M24*N$1) -> 0.017132711 | R24: 22 | S24: =IF(R24="","",SUMIFS($N$3:$N$10000,$E$3:$E$10000,R24)) -> 1.831944 | W24: População Finita | X24: =ROUNDUP((X14^2*X7)/((X20^2)+(X14^2*X7/B10)),0) -> 15
E25: =IF(DADOS!C25="","",DADOS!C25) -> 2 | F25: =IF(DADOS!E25="","",DADOS!E25) -> 18.5 | G25: =IF(DADOS!F25="","",DADOS!F25) -> 5 | K25: =IF(F25="","",F25/PI()) -> 5.8887329 | L25: =IF(K25="","",(PI()*K25^2)/40000) -> 0.002723539 | M25: =IF(L25="","",L25*G25) -> 0.013617695 | N25: =IF(M25="","",M25*N$1) -> 0.010894156 | R25: 23 | S25: =IF(R25="","",SUMIFS($N$3:$N$10000,$E$3:$E$10000,R25)) -> 3.3270724
E26: =IF(DADOS!C26="","",DADOS!C26) -> 2 | F26: =IF(DADOS!E26="","",DADOS!E26) -> 18 | G26: =IF(DADOS!F26="","",DADOS!F26) -> 3 | K26: =IF(F26="","",F26/PI()) -> 5.729578 | L26: =IF(K26="","",(PI()*K26^2)/40000) -> 0.0025783101 | M26: =IF(L26="","",L26*G26) -> 0.0077349302 | N26: =IF(M26="","",M26*N$1) -> 0.0061879442 | R26: 24 | S26: =IF(R26="","",SUMIFS($N$3:$N$10000,$E$3:$E$10000,R26)) -> 7.2080019
E27: =IF(DADOS!C27="","",DADOS!C27) -> 2 | F27: =IF(DADOS!E27="","",DADOS!E27) -> 17.2 | G27: =IF(DADOS!F27="","",DADOS!F27) -> 3.5 | K27: =IF(F27="","",F27/PI()) -> 5.47493 | L27: =IF(K27="","",(PI()*K27^2)/40000) -> 0.0023542199 | M27: =IF(L27="","",L27*G27) -> 0.0082397697 | N27: =IF(M27="","",M27*N$1) -> 0.0065918158 | R27: 25 | S27: =IF(R27="","",SUMIFS($N$3:$N$10000,$E$3:$E$10000,R27)) -> 1.4882652
E28: =IF(DADOS!C28="","",DADOS!C28) -> 2 | F28: =IF(DADOS!E28="","",DADOS!E28) -> 19.6 | G28: =IF(DADOS!F28="","",DADOS!F28) -> 4 | K28: =IF(F28="","",F28/PI()) -> 6.2388738 | L28: =IF(K28="","",(PI()*K28^2)/40000) -> 0.0030570481 | M28: =IF(L28="","",L28*G28) -> 0.012228193 | N28: =IF(M28="","",M28*N$1) -> 0.0097825541 | R28: 26 | S28: =IF(R28="","",SUMIFS($N$3:$N$10000,$E$3:$E$10000,R28)) -> 4.9438305
E29: =IF(DADOS!C29="","",DADOS!C29) -> 2 | F29: =IF(DADOS!E29="","",DADOS!E29) -> 18 | G29: =IF(DADOS!F29="","",DADOS!F29) -> 4 | K29: =IF(F29="","",F29/PI()) -> 5.729578 | L29: =IF(K29="","",(PI()*K29^2)/40000) -> 0.0025783101 | M29: =IF(L29="","",L29*G29) -> 0.01031324 | N29: =IF(M29="","",M29*N$1) -> 0.0082505922 | R29: 27 | S29: =IF(R29="","",SUMIFS($N$3:$N$10000,$E$3:$E$10000,R29)) -> 2.1473742
E30: =IF(DADOS!C30="","",DADOS!C30) -> 2 | F30: =IF(DADOS!E30="","",DADOS!E30) -> 52 | G30: =IF(DADOS!F30="","",DADOS!F30) -> 6 | K30: =IF(F30="","",F30/PI()) -> 16.552114 | L30: =IF(K30="","",(PI()*K30^2)/40000) -> 0.021517748 | M30: =IF(L30="","",L30*G30) -> 0.12910649 | N30: =IF(M30="","",M30*N$1) -> 0.10328519 | R30: 28 | S30: =IF(R30="","",SUMIFS($N$3:$N$10000,$E$3:$E$10000,R30)) -> 4.3098823
E31: =IF(DADOS!C31="","",DADOS!C31) -> 2 | F31: =IF(DADOS!E31="","",DADOS!E31) -> 29 | G31: =IF(DADOS!F31="","",DADOS!F31) -> 6 | K31: =IF(F31="","",F31/PI()) -> 9.2309867 | L31: =IF(K31="","",(PI()*K31^2)/40000) -> 0.0066924654 | M31: =IF(L31="","",L31*G31) -> 0.040154792 | N31: =IF(M31="","",M31*N$1) -> 0.032123834 | R31: 29 | S31: =IF(R31="","",SUMIFS($N$3:$N$10000,$E$3:$E$10000,R31)) -> 1.1841104
E32: =IF(DADOS!C32="","",DADOS!C32) -> 2 | F32: =IF(DADOS!E32="","",DADOS!E32) -> 46.5 | G32: =IF(DADOS!F32="","",DADOS!F32) -> 8 | K32: =IF(F32="","",F32/PI()) -> 14.80141 | L32: =IF(K32="","",(PI()*K32^2)/40000) -> 0.017206639 | M32: =IF(L32="","",L32*G32) -> 0.13765311 | N32: =IF(M32="","",M32*N$1) -> 0.11012249 | R32: 30 | S32: =IF(R32="","",SUMIFS($N$3:$N$10000,$E$3:$E$10000,R32)) -> 2.9407232
E33: =IF(DADOS!C33="","",DADOS!C33) -> 2 | F33: =IF(DADOS!E33="","",DADOS!E33) -> 50.2 | G33: =IF(DADOS!F33="","",DADOS!F33) -> 8 | K33: =IF(F33="","",F33/PI()) -> 15.979156 | L33: =IF(K33="","",(PI()*K33^2)/40000) -> 0.020053841 | M33: =IF(L33="","",L33*G33) -> 0.16043073 | N33: =IF(M33="","",M33*N$1) -> 0.12834458 | S33: =IF(R33="","",SUMIFS($N$3:$N$10000,$E$3:$E$10000,R33))
E34: =IF(DADOS!C34="","",DADOS!C34) -> 2 | F34: =IF(DADOS!E34="","",DADOS!E34) -> 39.5 | G34: =IF(DADOS!F34="","",DADOS!F34) -> 8 | K34: =IF(F34="","",F34/PI()) -> 12.573241 | L34: =IF(K34="","",(PI()*K34^2)/40000) -> 0.012416075 | M34: =IF(L34="","",L34*G34) -> 0.0993286 | N34: =IF(M34="","",M34*N$1) -> 0.07946288 | S34: =IF(R34="","",SUMIFS($N$3:$N$10000,$E$3:$E$10000,R34))
E35: =IF(DADOS!C35="","",DADOS!C35) -> 2 | F35: =IF(DADOS!E35="","",DADOS!E35) -> 65.2 | G35: =IF(DADOS!F35="","",DADOS!F35) -> 9 | K35: =IF(F35="","",F35/PI()) -> 20.753805 | L35: =IF(K35="","",(PI()*K35^2)/40000) -> 0.033828701 | M35: =IF(L35="","",L35*G35) -> 0.30445831 | N35: =IF(M35="","",M35*N$1) -> 0.24356665 | S35: =IF(R35="","",SUMIFS($N$3:$N$10000,$E$3:$E$10000,R35))
E36: =IF(DADOS!C36="","",DADOS!C36) -> 2 | F36: =IF(DADOS!E36="","",DADOS!E36) -> 85.2 | G36: =IF(DADOS!F36="","",DADOS!F36) -> 10 | K36: =IF(F36="","",F36/PI()) -> 27.120002 | L36: =IF(K36="","",(PI()*K36^2)/40000) -> 0.057765605 | M36: =IF(L36="","",L36*G36) -> 0.57765605 | N36: =IF(M36="","",M36*N$1) -> 0.46212484 | S36: =IF(R36="","",SUMIFS($N$3:$N$10000,$E$3:$E$10000,R36))
E37: =IF(DADOS!C37="","",DADOS!C37) -> 2 | F37: =IF(DADOS!E37="","",DADOS!E37) -> 64.2 | G37: =IF(DADOS!F37="","",DADOS!F37) -> 8 | K37: =IF(F37="","",F37/PI()) -> 20.435495 | L37: =IF(K37="","",(PI()*K37^2)/40000) -> 0.032798969 | M37: =IF(L37="","",L37*G37) -> 0.26239175 | N37: =IF(M37="","",M37*N$1) -> 0.2099134 | S37: =IF(R37="","",SUMIFS($N$3:$N$10000,$E$3:$E$10000,R37))
E38: =IF(DADOS!C38="","",DADOS!C38) -> 2 | F38: =IF(DADOS!E38="","",DADOS!E38) -> 85.2 | G38: =IF(DADOS!F38="","",DADOS!F38) -> 9 | K38: =IF(F38="","",F38/PI()) -> 27.120002 | L38: =IF(K38="","",(PI()*K38^2)/40000) -> 0.057765605 | M38: =IF(L38="","",L38*G38) -> 0.51989044 | N38: =IF(M38="","",M38*N$1) -> 0.41591236 | S38: =IF(R38="","",SUMIFS($N$3:$N$10000,$E$3:$E$10000,R38))
E39: =IF(DADOS!C39="","",DADOS!C39) -> 2 | F39: =IF(DADOS!E39="","",DADOS!E39) -> 55.1 | G39: =IF(DADOS!F39="","",DADOS!F39) -> 10 | K39: =IF(F39="","",F39/PI()) -> 17.538875 | L39: =IF(K39="","",(PI()*K39^2)/40000) -> 0.0241598 | M39: =IF(L39="","",L39*G39) -> 0.241598 | N39: =IF(M39="","",M39*N$1) -> 0.1932784 | S39: =IF(R39="","",SUMIFS($N$3:$N$10000,$E$3:$E$10000,R39))
E40: =IF(DADOS!C40="","",DADOS!C40) -> 2 | F40: =IF(DADOS!E40="","",DADOS!E40) -> 77.5 | G40: =IF(DADOS!F40="","",DADOS!F40) -> 9.5 | K40: =IF(F40="","",F40/PI()) -> 24.669016 | L40: =IF(K40="","",(PI()*K40^2)/40000) -> 0.047796219 | M40: =IF(L40="","",L40*G40) -> 0.45406408 | N40: =IF(M40="","",M40*N$1) -> 0.36325126 | S40: =IF(R40="","",SUMIFS($N$3:$N$10000,$E$3:$E$10000,R40))
...
